//                                               -*- C++ -*-
/**
 *  @file  t_NumericalMathFunction_exec_sample_no_retry.cxx
 *  @brief The test file of class NumericalMathFunction for failed execution with samples
 *
 *  Copyright (C) 2005-2013 EDF-EADS-Phimeca
 *
 *  This library is free software: you can redistribute it and/or modify
 *  it under the terms of the GNU Lesser General Public License as published by
 *  the Free Software Foundation, either version 3 of the License, or
 *  (at your option) any later version.
 *
 *  This library is distributed in the hope that it will be useful,
 *  but WITHOUT ANY WARRANTY; without even the implied warranty of
 *  MERCHANTABILITY or FITNESS FOR A PARTICULAR PURPOSE.  See the
 *  GNU Lesser General Public License for more details.
 *
 *  You should have received a copy of the GNU Lesser General Public
 *  along with this library.  If not, see <http://www.gnu.org/licenses/>.
 *
 *  @author schueller
 *  @date   2009-09-30 17:51:57 +0200 (Wed, 30 Sep 2009)
 */
#include "OT.hxx"
#include "OTtestcode.hxx"

using namespace OT;
using namespace OT::Test;

int main(int argc, char *argv[])
{
  TESTPREAMBLE;
  OStream fullprint(std::cout);

  try
    {

      /** Instance creation */
      NumericalMathFunction deviation("poutre_sample_no_retry");

      UnsignedLong size(10);
      NumericalSample inSample(size, 4);
      NumericalSample outSample1(size, 1);
      for(UnsignedLong i = 0; i < size; i++)
        {
          NumericalScalar fact(1.0 + NumericalScalar(i) / size);
          inSample[i][0] = 210.e9 * fact;
          inSample[i][1] = 1000.0 * fact;
          inSample[i][2] = 1.5 * fact;
          inSample[i][3] = 2.e-6 * fact;
          outSample1[i]  = deviation( inSample[i] );
        }

      fullprint << "outSample by point evaluation=" << outSample1 << std::endl;

      try
        {
          NumericalSample outSample2( deviation(inSample) );
          fullprint << "outSample by sample evaluation=" << outSample2 << std::endl;
          throw TestFailed( "Sample evaluation should have failed !" );

        }
      catch (Exception & ex)
        {
          fullprint << "Sample evaluation expected to fail" << std::endl;
        }

    }
  catch (TestFailed & ex)
    {
      std::cerr << ex << std::endl;
      return ExitCode::Error;
    }


  return ExitCode::Success;
}
